
2024-03-29 21:10:49,964 - INFO - Процесс для stesh был запущен
2024-03-29 21:11:06,720 - INFO - Авторизация stesh
2024-03-29 21:11:24,738 - INFO - Процесс для nogoeva был запущен
2024-03-29 21:11:47,917 - INFO - Информация о свободной дате отсутствует, ожидаем ...
2024-03-29 21:11:49,645 - ERROR - Ошибка в record_in_date - 
没有找到元素。
args: {'locator': None}
2024-03-29 21:11:50,887 - ERROR - Процесс для nogoeva был завершён
2024-03-29 21:12:03,304 - INFO - Авторизация nogoeva
2024-03-29 21:13:06,919 - INFO - В check_is_ele страницу обновил stesh
2024-03-29 21:13:19,150 - INFO - Информация о свободной дате отсутствует, ожидаем ...
2024-03-29 21:14:51,153 - INFO - В check_is_ele страницу обновил nogoeva
2024-03-29 21:15:02,926 - INFO - Информация о свободной дате отсутствует, ожидаем ...
2024-03-29 21:16:12,930 - INFO - В check_is_ele страницу обновил stesh
2024-03-29 21:16:23,801 - INFO - Информация о свободной дате отсутствует, ожидаем ...
2024-03-29 21:17:57,804 - INFO - В check_is_ele страницу обновил nogoeva
2024-03-29 21:18:08,654 - INFO - Информация о свободной дате отсутствует, ожидаем ...
2024-03-29 21:19:25,657 - INFO - В check_is_ele страницу обновил stesh
2024-03-29 21:19:38,024 - INFO - Информация о свободной дате отсутствует, ожидаем ...
2024-03-29 21:21:21,027 - INFO - В check_is_ele страницу обновил nogoeva
2024-03-29 21:21:33,038 - INFO - Информация о свободной дате отсутствует, ожидаем ...
2024-03-29 21:22:52,041 - INFO - В check_is_ele страницу обновил stesh
2024-03-29 21:23:02,456 - INFO - Информация о свободной дате отсутствует, ожидаем ...
2024-03-29 21:24:36,459 - INFO - В check_is_ele страницу обновил nogoeva
2024-03-29 21:24:46,851 - INFO - Информация о свободной дате отсутствует, ожидаем ...
2024-03-29 21:26:06,853 - INFO - В check_is_ele страницу обновил stesh
2024-03-29 21:26:18,708 - INFO - Информация о свободной дате отсутствует, ожидаем ...
2024-03-29 21:27:53,711 - INFO - В check_is_ele страницу обновил nogoeva
2024-03-29 21:28:05,820 - INFO - Информация о свободной дате отсутствует, ожидаем ...
2024-03-29 21:29:43,823 - INFO - В check_is_ele страницу обновил stesh
2024-03-29 21:29:54,342 - INFO - Информация о свободной дате отсутствует, ожидаем ...
2024-03-29 21:30:19,311 - ERROR - Infinity polling: polling exited
2024-03-29 21:30:19,312 - ERROR - Break infinity polling
2024-03-29 21:32:01,050 - INFO - Процесс для nogoeva был запущен
2024-03-29 21:32:16,612 - INFO - Авторизация nogoeva
2024-03-29 21:32:18,485 - ERROR - Infinity polling exception: HTTPSConnectionPool(host='api.telegram.org', port=443): Max retries exceeded with url: /bot6908556164:AAHNXT3CCUv0VLQBZl_m7F-hl5zF9cW_BIw/sendMessage?chat_id=741091047&text=%D0%A3%D0%BA%D0%B0%D0%B6%D0%B8%D1%82%D0%B5+%D0%B0%D0%B4%D1%80%D0%B5%D1%81+%D1%8D%D0%BB%D0%B5%D0%BA%D1%82%D1%80%D0%BE%D0%BD%D0%BD%D0%BE%D0%B9+%D0%BF%D0%BE%D1%87%D1%82%D1%8B+%D0%B4%D0%BB%D1%8F+%D0%B0%D0%B2%D1%82%D0%BE%D1%80%D0%B8%D0%B7%D0%B0%D1%86%D0%B8%D0%B8 (Caused by NewConnectionError('<urllib3.connection.HTTPSConnection object at 0x7e76a9820fd0>: Failed to establish a new connection: [Errno 101] Network is unreachable'))
2024-03-29 21:32:18,490 - ERROR - Exception traceback:
Traceback (most recent call last):
  File "/home/roman/projects/bot_register_date/env/lib/python3.11/site-packages/urllib3/connection.py", line 198, in _new_conn
    sock = connection.create_connection(
           ^^^^^^^^^^^^^^^^^^^^^^^^^^^^^
  File "/home/roman/projects/bot_register_date/env/lib/python3.11/site-packages/urllib3/util/connection.py", line 85, in create_connection
    raise err
  File "/home/roman/projects/bot_register_date/env/lib/python3.11/site-packages/urllib3/util/connection.py", line 73, in create_connection
    sock.connect(sa)
OSError: [Errno 101] Network is unreachable

The above exception was the direct cause of the following exception:

Traceback (most recent call last):
  File "/home/roman/projects/bot_register_date/env/lib/python3.11/site-packages/urllib3/connectionpool.py", line 793, in urlopen
    response = self._make_request(
               ^^^^^^^^^^^^^^^^^^^
  File "/home/roman/projects/bot_register_date/env/lib/python3.11/site-packages/urllib3/connectionpool.py", line 491, in _make_request
    raise new_e
  File "/home/roman/projects/bot_register_date/env/lib/python3.11/site-packages/urllib3/connectionpool.py", line 467, in _make_request
    self._validate_conn(conn)
  File "/home/roman/projects/bot_register_date/env/lib/python3.11/site-packages/urllib3/connectionpool.py", line 1099, in _validate_conn
    conn.connect()
  File "/home/roman/projects/bot_register_date/env/lib/python3.11/site-packages/urllib3/connection.py", line 616, in connect
    self.sock = sock = self._new_conn()
                       ^^^^^^^^^^^^^^^^
  File "/home/roman/projects/bot_register_date/env/lib/python3.11/site-packages/urllib3/connection.py", line 213, in _new_conn
    raise NewConnectionError(
urllib3.exceptions.NewConnectionError: <urllib3.connection.HTTPSConnection object at 0x7e76a9820fd0>: Failed to establish a new connection: [Errno 101] Network is unreachable

The above exception was the direct cause of the following exception:

Traceback (most recent call last):
  File "/home/roman/projects/bot_register_date/env/lib/python3.11/site-packages/requests/adapters.py", line 486, in send
    resp = conn.urlopen(
           ^^^^^^^^^^^^^
  File "/home/roman/projects/bot_register_date/env/lib/python3.11/site-packages/urllib3/connectionpool.py", line 847, in urlopen
    retries = retries.increment(
              ^^^^^^^^^^^^^^^^^^
  File "/home/roman/projects/bot_register_date/env/lib/python3.11/site-packages/urllib3/util/retry.py", line 515, in increment
    raise MaxRetryError(_pool, url, reason) from reason  # type: ignore[arg-type]
    ^^^^^^^^^^^^^^^^^^^^^^^^^^^^^^^^^^^^^^^^^^^^^^^^^^^
urllib3.exceptions.MaxRetryError: HTTPSConnectionPool(host='api.telegram.org', port=443): Max retries exceeded with url: /bot6908556164:AAHNXT3CCUv0VLQBZl_m7F-hl5zF9cW_BIw/sendMessage?chat_id=741091047&text=%D0%A3%D0%BA%D0%B0%D0%B6%D0%B8%D1%82%D0%B5+%D0%B0%D0%B4%D1%80%D0%B5%D1%81+%D1%8D%D0%BB%D0%B5%D0%BA%D1%82%D1%80%D0%BE%D0%BD%D0%BD%D0%BE%D0%B9+%D0%BF%D0%BE%D1%87%D1%82%D1%8B+%D0%B4%D0%BB%D1%8F+%D0%B0%D0%B2%D1%82%D0%BE%D1%80%D0%B8%D0%B7%D0%B0%D1%86%D0%B8%D0%B8 (Caused by NewConnectionError('<urllib3.connection.HTTPSConnection object at 0x7e76a9820fd0>: Failed to establish a new connection: [Errno 101] Network is unreachable'))

During handling of the above exception, another exception occurred:

Traceback (most recent call last):
  File "/home/roman/projects/bot_register_date/env/lib/python3.11/site-packages/telebot/__init__.py", line 955, in infinity_polling
    self.polling(non_stop=True, timeout=timeout, long_polling_timeout=long_polling_timeout,
  File "/home/roman/projects/bot_register_date/env/lib/python3.11/site-packages/telebot/__init__.py", line 1043, in polling
    self.__threaded_polling(non_stop=non_stop, interval=interval, timeout=timeout, long_polling_timeout=long_polling_timeout,
  File "/home/roman/projects/bot_register_date/env/lib/python3.11/site-packages/telebot/__init__.py", line 1118, in __threaded_polling
    raise e
  File "/home/roman/projects/bot_register_date/env/lib/python3.11/site-packages/telebot/__init__.py", line 1074, in __threaded_polling
    self.worker_pool.raise_exceptions()
  File "/home/roman/projects/bot_register_date/env/lib/python3.11/site-packages/telebot/util.py", line 147, in raise_exceptions
    raise self.exception_info
  File "/home/roman/projects/bot_register_date/env/lib/python3.11/site-packages/telebot/util.py", line 90, in run
    task(*args, **kwargs)
  File "/home/roman/projects/bot_register_date/env/lib/python3.11/site-packages/telebot/__init__.py", line 6801, in _run_middlewares_and_handler
    result = handler['function'](message)
             ^^^^^^^^^^^^^^^^^^^^^^^^^^^^
  File "/home/roman/projects/bot_register_date/chrome_driver/dris.py", line 46, in get_login
    bot.send_message(message.chat.id, f'Укажите адрес электронной почты для авторизации')
  File "/home/roman/projects/bot_register_date/env/lib/python3.11/site-packages/telebot/__init__.py", line 1549, in send_message
    apihelper.send_message(
  File "/home/roman/projects/bot_register_date/env/lib/python3.11/site-packages/telebot/apihelper.py", line 264, in send_message
    return _make_request(token, method_url, params=payload, method='post')
           ^^^^^^^^^^^^^^^^^^^^^^^^^^^^^^^^^^^^^^^^^^^^^^^^^^^^^^^^^^^^^^^
  File "/home/roman/projects/bot_register_date/env/lib/python3.11/site-packages/telebot/apihelper.py", line 156, in _make_request
    result = _get_req_session().request(
             ^^^^^^^^^^^^^^^^^^^^^^^^^^^
  File "/home/roman/projects/bot_register_date/env/lib/python3.11/site-packages/requests/sessions.py", line 589, in request
    resp = self.send(prep, **send_kwargs)
           ^^^^^^^^^^^^^^^^^^^^^^^^^^^^^^
  File "/home/roman/projects/bot_register_date/env/lib/python3.11/site-packages/requests/sessions.py", line 703, in send
    r = adapter.send(request, **kwargs)
        ^^^^^^^^^^^^^^^^^^^^^^^^^^^^^^^
  File "/home/roman/projects/bot_register_date/env/lib/python3.11/site-packages/requests/adapters.py", line 519, in send
    raise ConnectionError(e, request=request)
requests.exceptions.ConnectionError: HTTPSConnectionPool(host='api.telegram.org', port=443): Max retries exceeded with url: /bot6908556164:AAHNXT3CCUv0VLQBZl_m7F-hl5zF9cW_BIw/sendMessage?chat_id=741091047&text=%D0%A3%D0%BA%D0%B0%D0%B6%D0%B8%D1%82%D0%B5+%D0%B0%D0%B4%D1%80%D0%B5%D1%81+%D1%8D%D0%BB%D0%B5%D0%BA%D1%82%D1%80%D0%BE%D0%BD%D0%BD%D0%BE%D0%B9+%D0%BF%D0%BE%D1%87%D1%82%D1%8B+%D0%B4%D0%BB%D1%8F+%D0%B0%D0%B2%D1%82%D0%BE%D1%80%D0%B8%D0%B7%D0%B0%D1%86%D0%B8%D0%B8 (Caused by NewConnectionError('<urllib3.connection.HTTPSConnection object at 0x7e76a9820fd0>: Failed to establish a new connection: [Errno 101] Network is unreachable'))

2024-03-29 21:32:36,673 - ERROR - Threaded polling exception: A request to the Telegram API was unsuccessful. Error code: 502. Description: Bad Gateway
2024-03-29 21:32:36,675 - ERROR - Exception traceback:
Traceback (most recent call last):
  File "/home/roman/projects/bot_register_date/env/lib/python3.11/site-packages/telebot/__init__.py", line 1073, in __threaded_polling
    polling_thread.raise_exceptions()
  File "/home/roman/projects/bot_register_date/env/lib/python3.11/site-packages/telebot/util.py", line 108, in raise_exceptions
    raise self.exception_info
  File "/home/roman/projects/bot_register_date/env/lib/python3.11/site-packages/telebot/util.py", line 90, in run
    task(*args, **kwargs)
  File "/home/roman/projects/bot_register_date/env/lib/python3.11/site-packages/telebot/__init__.py", line 649, in __retrieve_updates
    updates = self.get_updates(offset=(self.last_update_id + 1),
             ^^^^^^^^^^^^^^^^^^^^^^^^^^^^^^^^^^^^^^^^^^^^^^^^^^^
  File "/home/roman/projects/bot_register_date/env/lib/python3.11/site-packages/telebot/__init__.py", line 623, in get_updates
    json_updates = apihelper.get_updates(self.token, offset, limit, timeout, allowed_updates, long_polling_timeout)
                   ^^^^^^^^^^^^^^^^^^^^^^^^^^^^^^^^^^^^^^^^^^^^^^^^^^^^^^^^^^^^^^^^^^^^^^^^^^^^^^^^^^^^^^^^^^^^^^^^
  File "/home/roman/projects/bot_register_date/env/lib/python3.11/site-packages/telebot/apihelper.py", line 321, in get_updates
    return _make_request(token, method_url, params=payload)
           ^^^^^^^^^^^^^^^^^^^^^^^^^^^^^^^^^^^^^^^^^^^^^^^^
  File "/home/roman/projects/bot_register_date/env/lib/python3.11/site-packages/telebot/apihelper.py", line 162, in _make_request
    json_result = _check_result(method_name, result)
                  ^^^^^^^^^^^^^^^^^^^^^^^^^^^^^^^^^^
  File "/home/roman/projects/bot_register_date/env/lib/python3.11/site-packages/telebot/apihelper.py", line 189, in _check_result
    raise ApiTelegramException(method_name, result, result_json)
telebot.apihelper.ApiTelegramException: A request to the Telegram API was unsuccessful. Error code: 502. Description: Bad Gateway

2024-03-29 21:32:37,076 - ERROR - Threaded polling exception: A request to the Telegram API was unsuccessful. Error code: 502. Description: Bad Gateway
2024-03-29 21:32:37,078 - ERROR - Exception traceback:
Traceback (most recent call last):
  File "/home/roman/projects/bot_register_date/env/lib/python3.11/site-packages/telebot/__init__.py", line 1073, in __threaded_polling
    polling_thread.raise_exceptions()
  File "/home/roman/projects/bot_register_date/env/lib/python3.11/site-packages/telebot/util.py", line 108, in raise_exceptions
    raise self.exception_info
  File "/home/roman/projects/bot_register_date/env/lib/python3.11/site-packages/telebot/util.py", line 90, in run
    task(*args, **kwargs)
  File "/home/roman/projects/bot_register_date/env/lib/python3.11/site-packages/telebot/__init__.py", line 649, in __retrieve_updates
    updates = self.get_updates(offset=(self.last_update_id + 1),
             ^^^^^^^^^^^^^^^^^^^^^^^^^^^^^^^^^^^^^^^^^^^^^^^^^^^
  File "/home/roman/projects/bot_register_date/env/lib/python3.11/site-packages/telebot/__init__.py", line 623, in get_updates
    json_updates = apihelper.get_updates(self.token, offset, limit, timeout, allowed_updates, long_polling_timeout)
                   ^^^^^^^^^^^^^^^^^^^^^^^^^^^^^^^^^^^^^^^^^^^^^^^^^^^^^^^^^^^^^^^^^^^^^^^^^^^^^^^^^^^^^^^^^^^^^^^^
  File "/home/roman/projects/bot_register_date/env/lib/python3.11/site-packages/telebot/apihelper.py", line 321, in get_updates
    return _make_request(token, method_url, params=payload)
           ^^^^^^^^^^^^^^^^^^^^^^^^^^^^^^^^^^^^^^^^^^^^^^^^
  File "/home/roman/projects/bot_register_date/env/lib/python3.11/site-packages/telebot/apihelper.py", line 162, in _make_request
    json_result = _check_result(method_name, result)
                  ^^^^^^^^^^^^^^^^^^^^^^^^^^^^^^^^^^
  File "/home/roman/projects/bot_register_date/env/lib/python3.11/site-packages/telebot/apihelper.py", line 189, in _check_result
    raise ApiTelegramException(method_name, result, result_json)
telebot.apihelper.ApiTelegramException: A request to the Telegram API was unsuccessful. Error code: 502. Description: Bad Gateway

2024-03-29 21:32:37,728 - ERROR - Threaded polling exception: A request to the Telegram API was unsuccessful. Error code: 502. Description: Bad Gateway
2024-03-29 21:32:37,730 - ERROR - Exception traceback:
Traceback (most recent call last):
  File "/home/roman/projects/bot_register_date/env/lib/python3.11/site-packages/telebot/__init__.py", line 1073, in __threaded_polling
    polling_thread.raise_exceptions()
  File "/home/roman/projects/bot_register_date/env/lib/python3.11/site-packages/telebot/util.py", line 108, in raise_exceptions
    raise self.exception_info
  File "/home/roman/projects/bot_register_date/env/lib/python3.11/site-packages/telebot/util.py", line 90, in run
    task(*args, **kwargs)
  File "/home/roman/projects/bot_register_date/env/lib/python3.11/site-packages/telebot/__init__.py", line 649, in __retrieve_updates
    updates = self.get_updates(offset=(self.last_update_id + 1),
             ^^^^^^^^^^^^^^^^^^^^^^^^^^^^^^^^^^^^^^^^^^^^^^^^^^^
  File "/home/roman/projects/bot_register_date/env/lib/python3.11/site-packages/telebot/__init__.py", line 623, in get_updates
    json_updates = apihelper.get_updates(self.token, offset, limit, timeout, allowed_updates, long_polling_timeout)
                   ^^^^^^^^^^^^^^^^^^^^^^^^^^^^^^^^^^^^^^^^^^^^^^^^^^^^^^^^^^^^^^^^^^^^^^^^^^^^^^^^^^^^^^^^^^^^^^^^
  File "/home/roman/projects/bot_register_date/env/lib/python3.11/site-packages/telebot/apihelper.py", line 321, in get_updates
    return _make_request(token, method_url, params=payload)
           ^^^^^^^^^^^^^^^^^^^^^^^^^^^^^^^^^^^^^^^^^^^^^^^^
  File "/home/roman/projects/bot_register_date/env/lib/python3.11/site-packages/telebot/apihelper.py", line 162, in _make_request
    json_result = _check_result(method_name, result)
                  ^^^^^^^^^^^^^^^^^^^^^^^^^^^^^^^^^^
  File "/home/roman/projects/bot_register_date/env/lib/python3.11/site-packages/telebot/apihelper.py", line 189, in _check_result
    raise ApiTelegramException(method_name, result, result_json)
telebot.apihelper.ApiTelegramException: A request to the Telegram API was unsuccessful. Error code: 502. Description: Bad Gateway

2024-03-29 21:32:58,030 - INFO - Информация о свободной дате отсутствует, ожидаем ...
2024-03-29 21:33:03,763 - ERROR - Infinity polling exception: HTTPSConnectionPool(host='api.telegram.org', port=443): Read timed out. (read timeout=25)
2024-03-29 21:33:03,768 - ERROR - Exception traceback:
Traceback (most recent call last):
  File "/home/roman/projects/bot_register_date/env/lib/python3.11/site-packages/urllib3/connectionpool.py", line 537, in _make_request
    response = conn.getresponse()
               ^^^^^^^^^^^^^^^^^^
  File "/home/roman/projects/bot_register_date/env/lib/python3.11/site-packages/urllib3/connection.py", line 466, in getresponse
    httplib_response = super().getresponse()
                       ^^^^^^^^^^^^^^^^^^^^^
  File "/usr/lib/python3.11/http/client.py", line 1378, in getresponse
    response.begin()
  File "/usr/lib/python3.11/http/client.py", line 318, in begin
    version, status, reason = self._read_status()
                              ^^^^^^^^^^^^^^^^^^^
  File "/usr/lib/python3.11/http/client.py", line 279, in _read_status
    line = str(self.fp.readline(_MAXLINE + 1), "iso-8859-1")
               ^^^^^^^^^^^^^^^^^^^^^^^^^^^^^^
  File "/usr/lib/python3.11/socket.py", line 706, in readinto
    return self._sock.recv_into(b)
           ^^^^^^^^^^^^^^^^^^^^^^^
  File "/usr/lib/python3.11/ssl.py", line 1311, in recv_into
    return self.read(nbytes, buffer)
           ^^^^^^^^^^^^^^^^^^^^^^^^^
  File "/usr/lib/python3.11/ssl.py", line 1167, in read
    return self._sslobj.read(len, buffer)
           ^^^^^^^^^^^^^^^^^^^^^^^^^^^^^^
TimeoutError: The read operation timed out

The above exception was the direct cause of the following exception:

Traceback (most recent call last):
  File "/home/roman/projects/bot_register_date/env/lib/python3.11/site-packages/requests/adapters.py", line 486, in send
    resp = conn.urlopen(
           ^^^^^^^^^^^^^
  File "/home/roman/projects/bot_register_date/env/lib/python3.11/site-packages/urllib3/connectionpool.py", line 847, in urlopen
    retries = retries.increment(
              ^^^^^^^^^^^^^^^^^^
  File "/home/roman/projects/bot_register_date/env/lib/python3.11/site-packages/urllib3/util/retry.py", line 470, in increment
    raise reraise(type(error), error, _stacktrace)
          ^^^^^^^^^^^^^^^^^^^^^^^^^^^^^^^^^^^^^^^^
  File "/home/roman/projects/bot_register_date/env/lib/python3.11/site-packages/urllib3/util/util.py", line 39, in reraise
    raise value
  File "/home/roman/projects/bot_register_date/env/lib/python3.11/site-packages/urllib3/connectionpool.py", line 793, in urlopen
    response = self._make_request(
               ^^^^^^^^^^^^^^^^^^^
  File "/home/roman/projects/bot_register_date/env/lib/python3.11/site-packages/urllib3/connectionpool.py", line 539, in _make_request
    self._raise_timeout(err=e, url=url, timeout_value=read_timeout)
  File "/home/roman/projects/bot_register_date/env/lib/python3.11/site-packages/urllib3/connectionpool.py", line 370, in _raise_timeout
    raise ReadTimeoutError(
urllib3.exceptions.ReadTimeoutError: HTTPSConnectionPool(host='api.telegram.org', port=443): Read timed out. (read timeout=25)

During handling of the above exception, another exception occurred:

Traceback (most recent call last):
  File "/home/roman/projects/bot_register_date/env/lib/python3.11/site-packages/telebot/__init__.py", line 955, in infinity_polling
    self.polling(non_stop=True, timeout=timeout, long_polling_timeout=long_polling_timeout,
  File "/home/roman/projects/bot_register_date/env/lib/python3.11/site-packages/telebot/__init__.py", line 1043, in polling
    self.__threaded_polling(non_stop=non_stop, interval=interval, timeout=timeout, long_polling_timeout=long_polling_timeout,
  File "/home/roman/projects/bot_register_date/env/lib/python3.11/site-packages/telebot/__init__.py", line 1118, in __threaded_polling
    raise e
  File "/home/roman/projects/bot_register_date/env/lib/python3.11/site-packages/telebot/__init__.py", line 1073, in __threaded_polling
    polling_thread.raise_exceptions()
  File "/home/roman/projects/bot_register_date/env/lib/python3.11/site-packages/telebot/util.py", line 108, in raise_exceptions
    raise self.exception_info
  File "/home/roman/projects/bot_register_date/env/lib/python3.11/site-packages/telebot/util.py", line 90, in run
    task(*args, **kwargs)
  File "/home/roman/projects/bot_register_date/env/lib/python3.11/site-packages/telebot/__init__.py", line 649, in __retrieve_updates
    updates = self.get_updates(offset=(self.last_update_id + 1),
             ^^^^^^^^^^^^^^^^^^^^^^^^^^^^^^^^^^^^^^^^^^^^^^^^^^^
  File "/home/roman/projects/bot_register_date/env/lib/python3.11/site-packages/telebot/__init__.py", line 623, in get_updates
    json_updates = apihelper.get_updates(self.token, offset, limit, timeout, allowed_updates, long_polling_timeout)
                   ^^^^^^^^^^^^^^^^^^^^^^^^^^^^^^^^^^^^^^^^^^^^^^^^^^^^^^^^^^^^^^^^^^^^^^^^^^^^^^^^^^^^^^^^^^^^^^^^
  File "/home/roman/projects/bot_register_date/env/lib/python3.11/site-packages/telebot/apihelper.py", line 321, in get_updates
    return _make_request(token, method_url, params=payload)
           ^^^^^^^^^^^^^^^^^^^^^^^^^^^^^^^^^^^^^^^^^^^^^^^^
  File "/home/roman/projects/bot_register_date/env/lib/python3.11/site-packages/telebot/apihelper.py", line 156, in _make_request
    result = _get_req_session().request(
             ^^^^^^^^^^^^^^^^^^^^^^^^^^^
  File "/home/roman/projects/bot_register_date/env/lib/python3.11/site-packages/requests/sessions.py", line 589, in request
    resp = self.send(prep, **send_kwargs)
           ^^^^^^^^^^^^^^^^^^^^^^^^^^^^^^
  File "/home/roman/projects/bot_register_date/env/lib/python3.11/site-packages/requests/sessions.py", line 703, in send
    r = adapter.send(request, **kwargs)
        ^^^^^^^^^^^^^^^^^^^^^^^^^^^^^^^
  File "/home/roman/projects/bot_register_date/env/lib/python3.11/site-packages/requests/adapters.py", line 532, in send
    raise ReadTimeout(e, request=request)
requests.exceptions.ReadTimeout: HTTPSConnectionPool(host='api.telegram.org', port=443): Read timed out. (read timeout=25)

2024-03-29 21:33:53,576 - INFO - Процесс для stesh был запущен
2024-03-29 21:34:08,795 - INFO - Авторизация stesh
2024-03-29 21:34:53,033 - INFO - В check_is_ele страницу обновил nogoeva
2024-03-29 21:35:15,070 - INFO - Информация о свободной дате отсутствует, ожидаем ...
2024-03-29 21:36:27,073 - INFO - В check_is_ele страницу обновил stesh
2024-03-29 21:36:49,223 - INFO - Информация о свободной дате отсутствует, ожидаем ...
2024-03-29 21:38:35,226 - INFO - В check_is_ele страницу обновил nogoeva
2024-03-29 21:38:46,317 - INFO - Информация о свободной дате отсутствует, ожидаем ...
2024-03-29 21:40:13,320 - INFO - В check_is_ele страницу обновил stesh
2024-03-29 21:40:25,031 - INFO - Информация о свободной дате отсутствует, ожидаем ...
2024-03-29 21:42:09,035 - INFO - В check_is_ele страницу обновил nogoeva
2024-03-29 21:42:30,995 - INFO - Информация о свободной дате отсутствует, ожидаем ...
2024-03-29 21:44:04,997 - INFO - В check_is_ele страницу обновил stesh
2024-03-29 21:44:27,503 - INFO - Информация о свободной дате отсутствует, ожидаем ...
2024-03-29 21:45:59,506 - INFO - В check_is_ele страницу обновил nogoeva
2024-03-29 21:46:10,304 - INFO - Информация о свободной дате отсутствует, ожидаем ...
2024-03-29 21:47:47,309 - INFO - В check_is_ele страницу обновил stesh
2024-03-29 21:47:58,127 - INFO - Информация о свободной дате отсутствует, ожидаем ...
2024-03-29 21:49:19,130 - INFO - В check_is_ele страницу обновил nogoeva
2024-03-29 21:49:41,013 - INFO - Информация о свободной дате отсутствует, ожидаем ...
2024-03-29 21:51:07,015 - INFO - В check_is_ele страницу обновил stesh
2024-03-29 21:51:28,924 - INFO - Информация о свободной дате отсутствует, ожидаем ...
2024-03-29 21:53:01,927 - INFO - В check_is_ele страницу обновил nogoeva
2024-03-29 21:53:12,801 - INFO - Информация о свободной дате отсутствует, ожидаем ...
2024-03-29 21:53:28,528 - ERROR - Infinity polling: polling exited
2024-03-29 21:53:28,529 - ERROR - Break infinity polling
2024-03-29 21:54:55,616 - INFO - Процесс для stesh был запущен
2024-03-29 21:55:11,004 - INFO - Авторизация stesh
2024-03-29 21:55:28,573 - INFO - Процесс для nogoeva был запущен
2024-03-29 21:55:44,567 - INFO - Авторизация nogoeva
2024-03-29 21:56:02,834 - INFO - Информация о свободной дате отсутствует, ожидаем ...
2024-03-29 21:57:23,837 - INFO - В check_is_ele страницу обновил stesh
2024-03-29 21:57:35,440 - INFO - Информация о свободной дате отсутствует, ожидаем ...
2024-03-29 21:59:14,443 - INFO - В check_is_ele страницу обновил nogoeva
2024-03-29 21:59:26,115 - INFO - Информация о свободной дате отсутствует, ожидаем ...
2024-03-29 22:00:53,118 - INFO - В check_is_ele страницу обновил stesh
2024-03-29 22:01:04,078 - INFO - Информация о свободной дате отсутствует, ожидаем ...
2024-03-29 22:02:32,081 - INFO - В check_is_ele страницу обновил nogoeva
2024-03-29 22:02:42,604 - INFO - Информация о свободной дате отсутствует, ожидаем ...
2024-03-29 22:04:20,607 - INFO - В check_is_ele страницу обновил stesh
2024-03-29 22:04:32,895 - INFO - Информация о свободной дате отсутствует, ожидаем ...
2024-03-29 22:05:43,898 - INFO - В check_is_ele страницу обновил nogoeva
2024-03-29 22:05:55,924 - INFO - Информация о свободной дате отсутствует, ожидаем ...
2024-03-29 22:07:05,926 - INFO - В check_is_ele страницу обновил stesh
2024-03-29 22:07:16,404 - INFO - Информация о свободной дате отсутствует, ожидаем ...
2024-03-29 22:08:43,407 - INFO - В check_is_ele страницу обновил nogoeva
2024-03-29 22:08:53,776 - INFO - Информация о свободной дате отсутствует, ожидаем ...
2024-03-29 22:10:31,779 - INFO - В check_is_ele страницу обновил stesh
2024-03-29 22:10:43,737 - INFO - Информация о свободной дате отсутствует, ожидаем ...
2024-03-29 22:12:15,740 - INFO - В check_is_ele страницу обновил nogoeva
2024-03-29 22:12:27,395 - INFO - Информация о свободной дате отсутствует, ожидаем ...
2024-03-29 22:13:52,398 - INFO - В check_is_ele страницу обновил stesh
2024-03-29 22:14:02,746 - INFO - Информация о свободной дате отсутствует, ожидаем ...
2024-03-29 22:15:38,749 - INFO - В check_is_ele страницу обновил nogoeva
2024-03-29 22:15:49,113 - INFO - Информация о свободной дате отсутствует, ожидаем ...
2024-03-29 22:17:28,116 - INFO - В check_is_ele страницу обновил stesh
2024-03-29 22:17:40,888 - INFO - Информация о свободной дате отсутствует, ожидаем ...
2024-03-29 22:18:50,890 - INFO - В check_is_ele страницу обновил nogoeva
2024-03-29 22:19:02,600 - INFO - Информация о свободной дате отсутствует, ожидаем ...
2024-03-29 22:20:18,603 - INFO - В check_is_ele страницу обновил stesh
2024-03-29 22:20:28,932 - INFO - Информация о свободной дате отсутствует, ожидаем ...
2024-03-29 22:22:11,934 - INFO - В check_is_ele страницу обновил nogoeva
2024-03-29 22:22:22,326 - INFO - Информация о свободной дате отсутствует, ожидаем ...
2024-03-29 22:23:32,329 - INFO - В check_is_ele страницу обновил stesh
2024-03-29 22:23:43,895 - INFO - Информация о свободной дате отсутствует, ожидаем ...
2024-03-29 22:25:08,897 - INFO - В check_is_ele страницу обновил nogoeva
2024-03-29 22:25:20,899 - INFO - Информация о свободной дате отсутствует, ожидаем ...
2024-03-29 22:26:35,901 - INFO - В check_is_ele страницу обновил stesh
2024-03-29 22:26:46,210 - INFO - Информация о свободной дате отсутствует, ожидаем ...
2024-03-29 22:28:01,213 - INFO - В check_is_ele страницу обновил nogoeva
2024-03-29 22:28:11,572 - INFO - Информация о свободной дате отсутствует, ожидаем ...
2024-03-29 22:29:45,575 - INFO - В check_is_ele страницу обновил stesh
2024-03-29 22:29:57,159 - INFO - Информация о свободной дате отсутствует, ожидаем ...
2024-03-29 22:31:40,162 - INFO - В check_is_ele страницу обновил nogoeva
2024-03-29 22:31:52,971 - INFO - Информация о свободной дате отсутствует, ожидаем ...
2024-03-29 22:33:10,974 - INFO - В check_is_ele страницу обновил stesh
2024-03-29 22:33:21,358 - INFO - Информация о свободной дате отсутствует, ожидаем ...
2024-03-29 22:35:01,360 - INFO - В check_is_ele страницу обновил nogoeva
2024-03-29 22:35:11,752 - INFO - Информация о свободной дате отсутствует, ожидаем ...
2024-03-29 22:36:26,755 - INFO - В check_is_ele страницу обновил stesh
2024-03-29 22:36:38,342 - INFO - Информация о свободной дате отсутствует, ожидаем ...
2024-03-29 22:38:32,345 - INFO - В check_is_ele страницу обновил nogoeva
2024-03-29 22:38:44,208 - INFO - Информация о свободной дате отсутствует, ожидаем ...
2024-03-29 22:40:33,211 - INFO - В check_is_ele страницу обновил stesh
2024-03-29 22:40:43,534 - INFO - Информация о свободной дате отсутствует, ожидаем ...
2024-03-29 22:42:36,536 - INFO - В check_is_ele страницу обновил nogoeva
2024-03-29 22:42:47,092 - INFO - Информация о свободной дате отсутствует, ожидаем ...
2024-03-29 22:44:26,095 - INFO - В check_is_ele страницу обновил stesh
2024-03-29 22:44:46,103 - INFO - Информация о свободной дате отсутствует, ожидаем ...
2024-03-29 22:46:07,106 - INFO - В check_is_ele страницу обновил nogoeva
2024-03-29 22:46:18,800 - INFO - Информация о свободной дате отсутствует, ожидаем ...
2024-03-29 22:47:47,802 - INFO - В check_is_ele страницу обновил stesh
2024-03-29 22:47:58,209 - INFO - Информация о свободной дате отсутствует, ожидаем ...
2024-03-29 22:49:41,211 - INFO - В check_is_ele страницу обновил nogoeva
2024-03-29 22:49:51,613 - INFO - Информация о свободной дате отсутствует, ожидаем ...
2024-03-29 22:51:06,616 - INFO - В check_is_ele страницу обновил stesh
2024-03-29 22:51:18,296 - INFO - Информация о свободной дате отсутствует, ожидаем ...
2024-03-29 22:52:58,299 - INFO - В check_is_ele страницу обновил nogoeva
2024-03-29 22:53:09,844 - INFO - Информация о свободной дате отсутствует, ожидаем ...
2024-03-29 22:54:53,847 - INFO - В check_is_ele страницу обновил stesh
2024-03-29 22:55:04,743 - INFO - Информация о свободной дате отсутствует, ожидаем ...
2024-03-29 22:56:25,745 - INFO - В check_is_ele страницу обновил nogoeva
2024-03-29 22:56:36,092 - INFO - Информация о свободной дате отсутствует, ожидаем ...
2024-03-29 22:58:30,095 - INFO - В check_is_ele страницу обновил stesh
2024-03-29 22:58:41,689 - INFO - Информация о свободной дате отсутствует, ожидаем ...
2024-03-29 23:00:34,692 - INFO - В check_is_ele страницу обновил nogoeva
2024-03-29 23:00:46,320 - INFO - Информация о свободной дате отсутствует, ожидаем ...
2024-03-29 23:02:14,322 - INFO - В check_is_ele страницу обновил stesh
2024-03-29 23:02:24,686 - INFO - Информация о свободной дате отсутствует, ожидаем ...
2024-03-29 23:04:14,689 - INFO - В check_is_ele страницу обновил nogoeva
2024-03-29 23:04:25,397 - INFO - Информация о свободной дате отсутствует, ожидаем ...
2024-03-29 23:06:05,400 - INFO - В check_is_ele страницу обновил stesh
2024-03-29 23:06:17,233 - INFO - Информация о свободной дате отсутствует, ожидаем ...
2024-03-29 23:07:40,236 - INFO - В check_is_ele страницу обновил nogoeva
2024-03-29 23:07:51,962 - INFO - Информация о свободной дате отсутствует, ожидаем ...
2024-03-29 23:09:08,964 - INFO - В check_is_ele страницу обновил stesh
2024-03-29 23:09:19,281 - INFO - Информация о свободной дате отсутствует, ожидаем ...
2024-03-29 23:10:53,303 - ERROR - Infinity polling: polling exited
2024-03-29 23:10:53,304 - ERROR - Break infinity polling
